Workbook

Sheet Легенда
A1: RetailBank · ИН-01 · Стоимость владения сервисом приоритизации и эффект
A3: Горизонт | B3: 24 месяца: месяцы 1–6 пилот, 7–9 вывод в прод, с месяца 10 эксплуатация (Д-30).
A4: Синий шрифт на жёлтом | B4: Входные значения: можно менять, все расчёты пересчитаются.
A5: Зелёный шрифт | B5: Формулы.
A6: Допущения | B6: Лист «Допущения»: ID, значение, источник, критичность для вывода.
A7: Рынок | B7: Лист «Рынок»: внешние цены с источником и датой обращения.
A8: TCO | B8: Лист «TCO»: разовые и регулярные статьи, итоги по годам и за 2 года.
A9: Эффект | B9: Лист «Эффект»: эффект против текущего процесса по сценариям прироста доли эскалаций; точки безубыточности.
A10: Единица | B10: Лист «Единица»: стоимость на операцию и на дополнительную эскалацию.
A11: Альтернативы | B11: Лист «Альтернативы»: стоимость отклонённых вариантов по рыночным ценам.
A12: Валюта | B12: Рубли с НДС, где источник приводит цены с НДС; внутренние ставки — полная стоимость часа для банка.

Sheet Рынок
A1: Внешние рыночные цены (обращение 2026-10-24)
A3: ID | B3: Позиция | C3: Цена | D3: Единица | E3: Источник | F3: Дата источника / обращения | G3: Где используется
A4: М-01 | B4: Yandex Cloud Compute: 1 vCPU (100%), Intel Ice Lake | C4: 1.24 | D4: ₽ / час | E4: https://yandex.cloud/ru/docs/compute/pricing (пример расчёта) | F4: дата цен на странице не указана; обращение 2026-10-24 | G4: Эквивалент стоимости вычислений для инфраструктуры в контуре банка
A5: М-02 | B5: Yandex Cloud Compute: 1 ГБ RAM, Intel Ice Lake | C5: 0.33 | D5: ₽ / час | E5: https://yandex.cloud/ru/docs/compute/pricing (пример расчёта) | F5: дата цен на странице не указана; обращение 2026-10-24 | G5: То же
A6: М-03 | B6: Cloud.ru Evolution: ВМ 1 vCPU / 1 ГБ RAM | C6: 1.2444 | D6: ₽ / час | E6: https://cdn.cloud.ru/docs/legal/tariffs/evolution/current-version/evolution-compute.pdf | F6: версия тарифа 261014; обращение 2026-10-24 | G6: Сверка порядка цен М-01/М-02
A7: М-04 | B7: Selectel DL24-NVMe: 2×Xeon Silver 4114 (20 ядер), 64 ГБ RAM, 2×960 ГБ NVMe | C7: 26800 | D7: ₽ / месяц с НДС | E7: https://www.whtop.com/plans/selectel.ru/148090 | F7: обновлено 2026-04-30; обращение 2026-10-24 | G7: Сверка: стоимость выделенного сервера как ориентир для on-premises
A8: М-05 | B8: Cloud.ru Advanced: ВМ с NVIDIA A100, 20 vCPU / 117 ГБ RAM (p3a.5xlarge.6, Linux) | C8: 456.9 | D8: ₽ / час с НДС | E8: https://cdn.cloud.ru/docs/legal/tariffs/advanced/future-version/gpu-accelerated.pdf | F8: версия тарифа 260403; обращение 2026-10-24 | G8: Альтернатива: своя языковая модель для назначения платежа (отклонена)
A9: М-06 | B9: GigaChat API Pro, pay-as-you-go, юрлица | C9: 500 | D9: ₽ / 1 млн токенов с НДС | E9: https://developers.sber.ru/docs/ru/gigachat/tariffs/legal-tariffs | F9: страница обновлена 2026-10-07; обращение 2026-10-24 | G9: Альтернатива: внешняя LLM для назначения платежа (отклонена по ЖО-3)
A10: М-07 | B10: GigaChat API Lite, pay-as-you-go, юрлица | C10: 65 | D10: ₽ / 1 млн токенов с НДС | E10: https://developers.sber.ru/docs/ru/gigachat/tariffs/legal-tariffs | F10: страница обновлена 2026-10-07; обращение 2026-10-24 | G10: То же
A11: М-08 | B11: GigaChat Embeddings, синхронный режим | C11: 14 | D11: ₽ / 1 млн токенов с НДС | E11: https://developers.sber.ru/docs/ru/gigachat/tariffs/legal-tariffs | F11: страница обновлена 2026-10-07; обращение 2026-10-24 | G11: То же

Sheet Допущения
A1: Допущения и входные значения
A3: ID | B3: Параметр | C3: Значение | D3: Единица | E3: Источник | F3: Критичность для вывода | G3: Комментарий
A4: Д-01 | B4: Помеченных операций в месяц | C4: 35000 | D4: операций | E4: из контекста кейса | F4: Средняя
A5: Д-02 | B5: Разбираемых операций в месяц (мощность службы) | C5: 10000 | D5: операций | E5: из контекста кейса | F5: Высокая | G5: Штат не меняется
A6: Д-03 | B6: ФОТ службы финмониторинга | C6: 45000000 | D6: ₽ / год | E6: из контекста кейса | F6: Высокая | G6: Основа стоимости разбора и эквивалента эскалации
A7: Д-04 | B7: Доля эскалаций среди разобранных сейчас (baseline) | C7: 0.04 | D7: доля | E7: из контекста кейса | F7: Средняя | G7: ~400 из 10 000
A8: Д-05 | B8: Численность службы | C8: 25 | D8: чел. | E8: из контекста кейса | F8: Низкая
A9: Д-06 | B9: Контрольная выборка | C9: 500 | D9: операций / мес | E9: ADR-001 | F9: Средняя | G9: Забирает мощность у ранжируемой части
A10: Д-07 | B10: Доля контрольной выборки на двойной разбор | C10: 0.1 | D10: доля | E10: ADR-001 | F10: Низкая
A11: Д-10 | B11: Полная стоимость часа DS/ML-инженера | C11: 3500 | D11: ₽ / час | E11: оценка: рыночный уровень оплаты с начислениями и накладными | F11: Средняя
A12: Д-11 | B12: Полная стоимость часа разработчика / дата-инженера | C12: 3000 | D12: ₽ / час | E12: оценка | F12: Средняя
A13: Д-12 | B13: Полная стоимость часа специалиста ИБ | C13: 3000 | D13: ₽ / час | E13: оценка | F13: Низкая
A14: Д-13 | B14: Полная стоимость часа комплаенса, DPO, юриста | C14: 3500 | D14: ₽ / час | E14: оценка | F14: Низкая
A15: Д-14 | B15: Рабочих часов в месяц на 1 FTE | C15: 165 | D15: часов | E15: оценка | F15: Низкая
A16: Д-20 | B16: Витрина признаков и меток из истории | C16: 480 | D16: часов DE | E16: оценка | F16: Средняя
A17: Д-21 | B17: Гайдлайн эскалации: эксперты финмониторинга | C17: 80 | D17: часов ФМ | E17: оценка | F17: Низкая
A18: Д-22 | B18: Гайдлайн эскалации: комплаенс | C18: 40 | D18: часов | E18: оценка | F18: Низкая
A19: Д-23 | B19: Сборка отложенного и приёмочного набора, сценарии С1–С8 | C19: 120 | D19: часов DS | E19: оценка | F19: Низкая
A20: Д-24 | B20: Обучение К1/К2, калибровка, приёмка | C20: 480 | D20: часов DS | E20: оценка | F20: Средняя
A21: Д-25 | B21: Сервисы: признаки, приоритизация, брокер, публикатор, журнал, реестр | C21: 1280 | D21: часов разработки | E21: аналогия: 2 разработчика × 4 месяца | F21: Высокая | G21: Самая крупная разовая статья
A22: Д-26 | B22: Доработка системы ФМ: приём приоритета, коды причин, обязательная причина решения, двойной разбор | C22: 400 | D22: часов разработки | E22: оценка; зависит от владельца системы ФМ | F22: Высокая | G22: Если система ФМ вендорская, цена может быть выше
A23: Д-27 | B23: Обучение аналитиков новому порядку и кодам причин | C23: 4 | D23: часов на аналитика | E23: оценка | F23: Низкая
A24: Д-28 | B24: Наблюдаемость: метрики по слоям, дашборды, алерты | C24: 160 | D24: часов разработки | E24: оценка | F24: Низкая
A25: Д-29 | B25: Безопасность: ИБ (учётки, подпись артефактов, проверка зависимостей) | C25: 160 | D25: часов ИБ | E25: оценка | F25: Низкая
A26: Д-31 | B26: Согласования: комплаенс, DPO, юристы (ВЮ-06, 07, 10, 11, 12) | C26: 160 | D26: часов | E26: оценка | F26: Средняя
A27: Д-32 | B27: Анализ теневого режима и двух рукавов | C27: 160 | D27: часов DS | E27: оценка | F27: Низкая
A28: Д-33 | B28: Вариант модели без признака внешней платформы (план выхода) | C28: 80 | D28: часов DS | E28: оценка | F28: Низкая
A29: Д-30 | B29: Месяц начала эксплуатации | C29: 10 | D29: месяц | E29: оценка: пилот 1–6, вывод в прод 7–9 | F29: Высокая | G29: Сдвиг на квартал снимает 3 месяца эффекта
A30: Д-34 | B30: Месяц начала прод-инфраструктуры | C30: 7 | D30: месяц | E30: оценка | F30: Низкая
A31: Д-40 | B31: Прод: vCPU (сервисы, брокер, БД с резервом) | C31: 32 | D31: vCPU | E31: оценка | F31: Низкая | G31: Модель на табличных данных, GPU не нужен
A32: Д-41 | B32: Прод: RAM | C32: 128 | D32: ГБ | E32: оценка | F32: Низкая
A33: Д-42 | B33: Среда DS: vCPU | C33: 16 | D33: vCPU | E33: оценка | F33: Низкая
A34: Д-43 | B34: Среда DS: RAM | C34: 64 | D34: ГБ | E34: оценка | F34: Низкая
A35: Д-44 | B35: Надбавка на диски, резервные копии, сеть | C35: 0.2 | D35: доля | E35: оценка | F35: Низкая
A36: Д-45 | B36: Часов в месяц работы инфраструктуры | C36: 730 | D36: часов | E36: 24 × 365 / 12 | F36: Низкая
A37: Д-46 | B37: Стоимость мощности в контуре банка ≈ рыночная аренда того же объёма | C37: 1 | D37: коэффициент | E37: аналогия: М-01, М-02, сверка М-03, М-04 | F37: Низкая | G37: Инфраструктура — малая доля TCO
A38: Д-50 | B38: Поддержка и дежурство | C38: 0.5 | D38: FTE разработчика | E38: оценка | F38: Высокая
A39: Д-51 | B39: Сопровождение модели: мониторинг, переобучение, разбор алертов | C39: 0.5 | D39: FTE DS | E39: оценка | F39: Высокая
A40: Д-52 | B40: Регрессионных прогонов в год | C40: 4 | D40: прогонов | E40: оценка: квартальное переобучение | F40: Низкая
A41: Д-53 | B41: Трудоёмкость одного регрессионного прогона с теневым режимом | C41: 40 | D41: часов DS | E41: оценка | F41: Низкая
...

Sheet TCO
A1: Стоимость владения ИН-01 на горизонте 24 месяцев, ₽
A3: ID | B3: Статья | C3: Категория | D3: Тип | E3: Расчёт | F3: Сумма разово / в месяц | G3: Месяц начала | H3: Год 1 | I3: Год 2 | J3: Итого 2 года
B4: Разовые
A5: Р-01 | B5: Данные: витрина признаков и меток из истории | C5: Данные и проверочные наборы | D5: разово | E5: Д-20 × Д-11 | F5: =Допущения!$C$16*Допущения!$C$12 -> 1440000 | G5: 1 | H5: =F5 -> 1440000 | I5: 0 | J5: =H5+I5 -> 1440000
A6: Р-02 | B6: Данные: гайдлайн эскалации (эксперты ФМ и комплаенс) | C6: Данные и проверочные наборы | D6: разово | E6: Д-21 × Д-91 + Д-22 × Д-13 | F6: =Допущения!$C$17*Допущения!$C$50+Допущения!$C$18*Допущения!$C$14 -> 290000 | G6: 1 | H6: =F6 -> 290000 | I6: 0 | J6: =H6+I6 -> 290000
A7: Р-03 | B7: Данные: отложенный и приёмочный набор, сценарии С1–С8 | C7: Данные и проверочные наборы | D7: разово | E7: Д-23 × Д-10 | F7: =Допущения!$C$19*Допущения!$C$11 -> 420000 | G7: 1 | H7: =F7 -> 420000 | I7: 0 | J7: =H7+I7 -> 420000
A8: Р-04 | B8: Модель: обучение К1/К2, калибровка, приёмка | C8: Модель | D8: разово | E8: Д-24 × Д-10 | F8: =Допущения!$C$20*Допущения!$C$11 -> 1680000 | G8: 1 | H8: =F8 -> 1680000 | I8: 0 | J8: =H8+I8 -> 1680000
A9: Р-05 | B9: Интеграция: сервисы признаков и приоритизации, брокер, публикатор, журнал, реестр | C9: Интеграция и разработка | D9: разово | E9: Д-25 × Д-11 | F9: =Допущения!$C$21*Допущения!$C$12 -> 3840000 | G9: 1 | H9: =F9 -> 3840000 | I9: 0 | J9: =H9+I9 -> 3840000
A10: Р-06 | B10: Ручной контур: доработка рабочего места в системе ФМ | C10: Ручной контур и интерфейс | D10: разово | E10: Д-26 × Д-11 | F10: =Допущения!$C$22*Допущения!$C$12 -> 1200000 | G10: 1 | H10: =F10 -> 1200000 | I10: 0 | J10: =H10+I10 -> 1200000
A11: Р-07 | B11: Ручной контур: обучение аналитиков | C11: Ручной контур и интерфейс | D11: разово | E11: Д-27 × Д-05 × Д-91 | F11: =Допущения!$C$23*Допущения!$C$8*Допущения!$C$50 -> 187500 | G11: 1 | H11: =F11 -> 187500 | I11: 0 | J11: =H11+I11 -> 187500
A12: Р-08 | B12: Наблюдаемость | C12: Наблюдаемость | D12: разово | E12: Д-28 × Д-11 | F12: =Допущения!$C$24*Допущения!$C$12 -> 480000 | G12: 1 | H12: =F12 -> 480000 | I12: 0 | J12: =H12+I12 -> 480000
A13: Р-09 | B13: Безопасность: ИБ | C13: Безопасность и соответствие | D13: разово | E13: Д-29 × Д-12 | F13: =Допущения!$C$25*Допущения!$C$13 -> 480000 | G13: 1 | H13: =F13 -> 480000 | I13: 0 | J13: =H13+I13 -> 480000
A14: Р-10 | B14: Соответствие: согласования с комплаенсом, DPO, юристами | C14: Безопасность и соответствие | D14: разово | E14: Д-31 × Д-13 | F14: =Допущения!$C$26*Допущения!$C$14 -> 560000 | G14: 1 | H14: =F14 -> 560000 | I14: 0 | J14: =H14+I14 -> 560000
A15: Р-11 | B15: Пилот: анализ теневого режима и двух рукавов | C15: Модель | D15: разово | E15: Д-32 × Д-10 | F15: =Допущения!$C$27*Допущения!$C$11 -> 560000 | G15: 1 | H15: =F15 -> 560000 | I15: 0 | J15: =H15+I15 -> 560000
A16: Р-12 | B16: Выход от поставщика: вариант модели без внешнего признака | C16: Миграция при смене поставщика | D16: разово | E16: Д-33 × Д-10 | F16: =Допущения!$C$28*Допущения!$C$11 -> 280000 | G16: 1 | H16: =F16 -> 280000 | I16: 0 | J16: =H16+I16 -> 280000
B17: Регулярные
A18: Р-20 | B18: Инфраструктура прода в контуре банка | C18: Инфраструктура | D18: в месяц | E18: (Д-40 × М-01 + Д-41 × М-02) × Д-45 × (1 + Д-44) × Д-46 | F18: =(Допущения!$C$31*Рынок!$C$4+Допущения!$C$32*Рынок!$C$5)*Допущения!$C$36*(1+Допущения!$C$35)*Допущения!$C$37 -> 71761.92 | G18: =Допущения!$C$30 -> 7 | H18: =F18*MAX(0,12-G18+1) -> 430571.52 | I18: =F18*MAX(0,24-MAX(G18,13)+1) -> 861143.04 | J18: =H18+I18 -> 1291714.6
A19: Р-21 | B19: Среда DS (обучение, приёмка, анализ) | C19: Инфраструктура | D19: в месяц | E19: (Д-42 × М-01 + Д-43 × М-02) × Д-45 × (1 + Д-44) × Д-46 | F19: =(Допущения!$C$33*Рынок!$C$4+Допущения!$C$34*Рынок!$C$5)*Допущения!$C$36*(1+Допущения!$C$35)*Допущения!$C$37 -> 35880.96 | G19: =1 -> 1 | H19: =F19*MAX(0,12-G19+1) -> 430571.52 | I19: =F19*MAX(0,24-MAX(G19,13)+1) -> 430571.52 | J19: =H19+I19 -> 861143.04
A20: Р-22 | B20: Контрольная выборка: разбор финмониторингом | C20: Данные и проверочные наборы; ручной контур | D20: в месяц | E20: Д-06 × Д-90 | F20: =Допущения!$C$9*Допущения!$C$49 -> 187500 | G20: =1 -> 1 | H20: =F20*MAX(0,12-G20+1) -> 2250000 | I20: =F20*MAX(0,24-MAX(G20,13)+1) -> 2250000 | J20: =H20+I20 -> 4500000
A21: Р-23 | B21: Двойной разбор части контрольной выборки | C21: Данные и проверочные наборы; ручной контур | D21: в месяц | E21: Д-06 × Д-07 × Д-90 | F21: =Допущения!$C$9*Допущения!$C$10*Допущения!$C$49 -> 18750 | G21: =1 -> 1 | H21: =F21*MAX(0,12-G21+1) -> 225000 | I21: =F21*MAX(0,24-MAX(G21,13)+1) -> 225000 | J21: =H21+I21 -> 450000
A22: Р-24 | B22: Поддержка и дежурство | C22: Поддержка | D22: в месяц | E22: Д-50 × Д-14 × Д-11 | F22: =Допущения!$C$38*Допущения!$C$15*Допущения!$C$12 -> 247500 | G22: =Допущения!$C$29 -> 10 | H22: =F22*MAX(0,12-G22+1) -> 742500 | I22: =F22*MAX(0,24-MAX(G22,13)+1) -> 2970000 | J22: =H22+I22 -> 3712500
A23: Р-25 | B23: Сопровождение модели | C23: Эксплуатация модели | D23: в месяц | E23: Д-51 × Д-14 × Д-10 | F23: =Допущения!$C$39*Допущения!$C$15*Допущения!$C$11 -> 288750 | G23: =Допущения!$C$29 -> 10 | H23: =F23*MAX(0,12-G23+1) -> 866250 | I23: =F23*MAX(0,24-MAX(G23,13)+1) -> 3465000 | J23: =H23+I23 -> 4331250
A24: Р-26 | B24: Обновления и регрессионные прогоны | C24: Обновления | D24: в месяц | E24: Д-52 × Д-53 × Д-10 / 12 | F24: =Допущения!$C$40*Допущения!$C$41*Допущения!$C$11/12 -> 46666.667 | G24: =Допущения!$C$29 -> 10 | H24: =F24*MAX(0,12-G24+1) -> 140000 | I24: =F24*MAX(0,24-MAX(G24,13)+1) -> 560000 | J24: =H24+I24 -> 700000
A25: Р-27 | B25: Безопасность и соответствие: ежегодно | C25: Безопасность и соответствие | D25: в месяц | E25: (Д-54 × Д-12 + Д-55 × Д-13) / 12 | F25: =(Допущения!$C$42*Допущения!$C$13+Допущения!$C$43*Допущения!$C$14)/12 -> 31666.667 | G25: =Допущения!$C$29 -> 10 | H25: =F25*MAX(0,12-G25+1) -> 95000 | I25: =F25*MAX(0,24-MAX(G25,13)+1) -> 380000 | J25: =H25+I25 -> 475000
A26: Р-28 | B26: Резерв на смену поставщика или библиотек | C26: Миграция при смене поставщика | D26: в месяц | E26: Д-56 × Д-10 / 12 | F26: =Допущения!$C$44*Допущения!$C$11/12 -> 11666.667 | G26: =Допущения!$C$29 -> 10 | H26: =F26*MAX(0,12-G26+1) -> 35000 | I26: =F26*MAX(0,24-MAX(G26,13)+1) -> 140000 | J26: =H26+I26 -> 175000
B27: Оплата API модели | C27: Вызовы модели | D27: — | E27: Не применимо: своя модель в контуре банка, оплаты за вызов нет | F27: 0 | G27: 0 | H27: 0 | I27: 0 | J27: 0
B29: Итого разовые | H29: =SUM(H5:H16) -> 11417500 | I29: =SUM(I5:I16) -> 0 | J29: =SUM(J5:J16) -> 11417500
B30: Итого регулярные | H30: =SUM(H18:H26) -> 5214893 | I30: =SUM(I18:I26) -> 11281715 | J30: =SUM(J18:J26) -> 16496608
B31: Стоимость владения | H31: =H29+H30 -> 16632393 | I31: =I29+I30 -> 11281715 | J31: =J29+J30 -> 27914108
B32: Регулярные расходы в установившемся режиме, в месяц | F32: =SUM(F18:F26) -> 940142.88
B33: Доля ручного контура (Р-22, Р-23) и людей в регулярных расходах | F33: =SUM(F20:F26)/F32 -> 0.8855037
B34: Доля инфраструктуры в регулярных расходах | F34: =(F18+F19)/F32 -> 0.1144963
B36: Стоимость до шлюза 1 (месяц 3: офлайн-проверка и контрольная выборка), ₽ | F36: =F5+F6+F7+F8+3*(F19+F20+F21) -> 4556392.9 | G36: Р-01…Р-04 + 3 месяца Р-21…Р-23: столько стоит узнать, есть ли сигнал, до вложений в интеграцию

Sheet Эффект
A1: Эффект против текущего процесса и безубыточность
A3: Метод | B3: Штат и мощность службы не меняются (Д-02). Модель меняет, что попадает в 9 500 ранжируемых разборов. Дополнительная эскалация оценивается тем, во что обошлось бы получить её ручным разбором при текущей доле 4% (Д-92, Д-60).
A5: Эффект на 1 п. п. прироста доли эскалаций, ₽ / мес | B5: =Допущения!$C$52/100*Допущения!$C$51 -> 890625
A6: Дополнительных эскалаций на 1 п. п., в месяц | B6: =Допущения!$C$52/100 -> 95
A8: Прирост доли эскалаций, п. п. | B8: Доля эскалаций в ранжируемой части | C8: Доп. эскалаций в месяц | D8: Эффект в месяц, ₽ | E8: Эффект за 2 года, ₽ | F8: Стоимость владения 2 года, ₽ | G8: Итог за 2 года, ₽ | H8: Итог в месяц в установившемся режиме, ₽
A9: 0.005 | B9: =Допущения!$C$7+A9 -> 0.045 | C9: =A9*Допущения!$C$52 -> 47.5 | D9: =C9*Допущения!$C$51 -> 445312.5 | E9: =D9*Допущения!$C$53 -> 6679687.5 | F9: =TCO!$J$31 -> 27914108 | G9: =E9-F9 -> -21234420 | H9: =D9-TCO!$F$32 -> -494830.38
A10: 0.01 | B10: =Допущения!$C$7+A10 -> 0.05 | C10: =A10*Допущения!$C$52 -> 95 | D10: =C10*Допущения!$C$51 -> 890625 | E10: =D10*Допущения!$C$53 -> 13359375 | F10: =TCO!$J$31 -> 27914108 | G10: =E10-F10 -> -14554733 | H10: =D10-TCO!$F$32 -> -49517.88
A11: 0.015 | B11: =Допущения!$C$7+A11 -> 0.055 | C11: =A11*Допущения!$C$52 -> 142.5 | D11: =C11*Допущения!$C$51 -> 1335937.5 | E11: =D11*Допущения!$C$53 -> 20039062 | F11: =TCO!$J$31 -> 27914108 | G11: =E11-F11 -> -7875045.1 | H11: =D11-TCO!$F$32 -> 395794.62
A12: 0.02 | B12: =Допущения!$C$7+A12 -> 0.06 | C12: =A12*Допущения!$C$52 -> 190 | D12: =C12*Допущения!$C$51 -> 1781250 | E12: =D12*Допущения!$C$53 -> 26718750 | F12: =TCO!$J$31 -> 27914108 | G12: =E12-F12 -> -1195357.6 | H12: =D12-TCO!$F$32 -> 841107.12
A13: 0.03 | B13: =Допущения!$C$7+A13 -> 0.07 | C13: =A13*Допущения!$C$52 -> 285 | D13: =C13*Допущения!$C$51 -> 2671875 | E13: =D13*Допущения!$C$53 -> 40078125 | F13: =TCO!$J$31 -> 27914108 | G13: =E13-F13 -> 12164017 | H13: =D13-TCO!$F$32 -> 1731732.1
A15: Безубыточность за 2 года, п. п. прироста | B15: =TCO!$J$31/($B$5*Допущения!$C$53)/100 -> 0.020894771 | C15: Прирост, при котором эффект за 24 месяца покрывает всю стоимость владения
A16: Покрытие эксплуатации, п. п. прироста | B16: =TCO!$F$32/$B$5/100 -> 0.01055599 | C16: Прирост, при котором ежемесячный эффект покрывает регулярные расходы (без возврата разовых)
A17: Базовый сценарий (Д-61): итог за 2 года, ₽ | B17: =Допущения!$C$46*Допущения!$C$52*Допущения!$C$51*Допущения!$C$53-TCO!$J$31 -> -1195357.6
A19: Источники эффекта
A20: Источник | B20: Учтён в деньгах | C20: Почему
A21: Рост доли эскалаций в разобранной выборке | B21: Да | C21: Есть baseline 4%, мощность 10 000 и ФОТ 45 млн ₽; эквивалент ручного разбора считается из кейса.
A22: Сокращение ручной работы на операцию | B22: Нет | C22: Сервис не меняет процедуру разбора; влияние кодов причин на 12 минут неизвестно, замеряется в пилоте.
A23: Более раннее выявление | B23: Нет | C23: В кейсе нет стоимости задержки выявления.
A24: Снижение лишних приостановок и жалоб (~450 снятых из ~600, ~120 жалоб в месяц) | B24: Нет | C24: Сервис не приостанавливает операции и не участвует в решении о приостановке; эффект не доказуем. Охраняется как guardrail.
A25: Ожидаемые регуляторные издержки (2 предписания за год) | B25: Нет | C25: Прямые издержки предписаний в кейсе не даны; связь эскалаций с предписаниями не измерена.

Sheet Единица
A1: Стоимость единицы
A3: Показатель | B3: Значение | C3: Расчёт
A4: Регулярные расходы на одну помеченную операцию, ₽ | B4: =TCO!$F$32/Допущения!$C$4 -> 26.861225 | C4: Установившиеся регулярные / Д-01
A5: Регулярные расходы на один разбор, ₽ | B5: =TCO!$F$32/Допущения!$C$5 -> 94.014288 | C5: Установившиеся регулярные / Д-02
A6: То же к стоимости разбора сегодня | B6: =B5/Допущения!$C$49 -> 0.25070477 | C6: к Д-90 (375 ₽)
A7: Стоимость владения за 2 года на одну помеченную операцию, ₽ | B7: =TCO!$J$31/(Допущения!$C$4*24) -> 33.23108 | C7: TCO 2 года / (Д-01 × 24)
A8: Целевой поток за 2 года, операций | B8: =Допущения!$C$4*24 -> 840000 | C8: Д-01 × 24
A9: Стоимость владения целевого потока за 2 года, ₽ | B9: =TCO!$J$31 -> 27914108 | C9: TCO, лист TCO
A10: Регулярная стоимость дополнительной эскалации при базовом сценарии, ₽ | B10: =TCO!$F$32/(Допущения!$C$46*Допущения!$C$52) -> 4948.1204 | C10: Установившиеся регулярные / доп. эскалаций
A11: Стоимость эскалации при текущем процессе, ₽ | B11: =Допущения!$C$51 -> 9375 | C11: Д-92

Sheet Альтернативы
A1: Отклонённые варианты текстового звена по рыночным ценам
A3: Токенов на одно назначение платежа с инструкцией | B3: 300 | C3: оценка
A5: Вариант | B5: Расчёт | C5: ₽ в месяц | D5: Почему отклонён
A6: Внешняя LLM (GigaChat Pro) для назначения платежа | B6: Д-01 × токенов / 1 млн × М-06 | C6: =Допущения!$C$4*$B$3/1000000*Рынок!$C$9 -> 5250 | D6: Дёшево, но сведения об операциях уходят за контур: ЖО-3 ADR-001. Цена не решает вопрос допустимости.
A7: Своя языковая модель на ВМ с A100 круглосуточно | B7: М-05 × Д-45 | C7: =Рынок!$C$8*Допущения!$C$36 -> 333537 | D7: Около трети всех регулярных расходов сервиса ради одного звена, где словарь не доказал недостаточности (Т3 в ADR-001); плюс эксплуатация GPU-контура, которого в банке нет (ВБ-20).
A8: Принято: словарь (Т1) в сервисе признаков | B8: входит в Р-05 и Р-20 | C8: 0 | D8: Без внешних вызовов и GPU.

Sheet Чувствительность
A1: Чувствительность: какие допущения переворачивают вывод
A3: Вариант | B3: Изменение | C3: Стоимость владения 2 года, ₽ | D3: Месяцев эффекта | E3: Эффект на 1 п. п. в месяц, ₽ | F3: Безубыточность за 2 года, п. п. | G3: Итог базового сценария (Д-61), ₽
A4: Базовый расчёт | B4: — | C4: =TCO!$J$31 -> 27914108 | D4: =Допущения!$C$53 -> 15 | E4: =Эффект!$B$5 -> 890625 | F4: =C4/(E4*D4)/100 -> 0.020894771 | G4: =Допущения!$C$46*100*E4*D4-C4 -> -1195357.6
A5: Интеграция вдвое дороже (Д-25, Д-26) | B5: + Р-05 + Р-06 | C5: =TCO!$J$31+TCO!$F$9+TCO!$F$10 -> 32954108 | D5: =Допущения!$C$53 -> 15 | E5: =Эффект!$B$5 -> 890625 | F5: =C5/(E5*D5)/100 -> 0.024667402 | G5: =Допущения!$C$46*100*E5*D5-C5 -> -6235357.6
A6: Запуск в эксплуатацию на квартал позже (Д-30) | B6: −3 месяца эффекта и эксплуатации | C6: =TCO!$J$31-3*(TCO!$F$22+TCO!$F$23+TCO!$F$24+TCO!$F$25+TCO!$F$26) -> 26035358 | D6: =Допущения!$C$53-3 -> 12 | E6: =Эффект!$B$5 -> 890625 | F6: =C6/(E6*D6)/100 -> 0.024360569 | G6: =Допущения!$C$46*100*E6*D6-C6 -> -4660357.6
A7: Поддержка и сопровождение вдвое больше (Д-50, Д-51) | B7: + (Р-24 + Р-25) × месяцев эксплуатации | C7: =TCO!$J$31+(TCO!$F$22+TCO!$F$23)*Допущения!$C$53 -> 35957858 | D7: =Допущения!$C$53 -> 15 | E7: =Эффект!$B$5 -> 890625 | F7: =C7/(E7*D7)/100 -> 0.026915823 | G7: =Допущения!$C$46*100*E7*D7-C7 -> -9239107.6
A8: Поддержка и сопровождение силами существующей платформенной команды: вдвое меньше | B8: − (Р-24 + Р-25) / 2 × месяцев эксплуатации | C8: =TCO!$J$31-(TCO!$F$22+TCO!$F$23)/2*Допущения!$C$53 -> 23892233 | D8: =Допущения!$C$53 -> 15 | E8: =Эффект!$B$5 -> 890625 | F8: =C8/(E8*D8)/100 -> 0.017884244 | G8: =Допущения!$C$46*100*E8*D8-C8 -> 2826517.4
A9: Бизнес ценит эскалацию вдвое ниже эквивалента ручного разбора (Д-60) | B9: эффект на 1 п. п. × 0,5 | C9: =TCO!$J$31 -> 27914108 | D9: =Допущения!$C$53 -> 15 | E9: =Эффект!$B$5*0.5 -> 445312.5 | F9: =C9/(E9*D9)/100 -> 0.041789541 | G9: =Допущения!$C$46*100*E9*D9-C9 -> -14554733
A10: Ставки DS и разработки в 1,5 раза выше (Д-10, Д-11) | B10: оценка сверху: × 1,5 к статьям с этими ставками | C10: =TCO!$J$31+0.5*(TCO!$J$5+TCO!$J$7+TCO!$J$8+TCO!$J$9+TCO!$J$10+TCO!$J$12+TCO!$J$15+TCO!$J$16+TCO!$J$22+TCO!$J$23+TCO!$J$24+TCO!$J$26) -> 37323483 | D10: =Допущения!$C$53 -> 15 | E10: =Эффект!$B$5 -> 890625 | F10: =C10/(E10*D10)/100 -> 0.027938045 | G10: =Допущения!$C$46*100*E10*D10-C10 -> -10604733
